Workbook

Sheet Overview
A1: FastAPI - Building Modern Backend APIs
A2: Take a student who knows Python and DBMS and turn them into someone who can design, secure, test, and ship a real backend API.
A4: Section | B4: Details
A5: Curriculum title | B5: FastAPI: Building Modern Backend APIs
A6: Format | B6: University-style, 15 weeks, runs as either a 3-credit (45 hours) or 4-credit (60 hours) course.
A7: Structure model | B7: Unit -> Topic (no chapters), matching the Python and DBMS curriculum format.
A8: Number of units | B8: 14 teaching units across 15 weeks.
A9: Teaching topics | B9: 129 topics total, sequenced in strict teaching order.
A10: Project chapters | B10: 9 mini projects and 1 capstone project, maintained as separate course-level chapters.
A11: Prerequisites | B11: Python Semester 1 and Semester 2 (functions, classes, modules, exceptions, decorators, virtual environments) and the DBMS course (SQL, keys, joins, transactions). No prior web development experience assumed.
A12: Tooling baseline | B12: Python 3.11+, FastAPI, Uvicorn, Pydantic v2, SQLAlchemy 2.x, Alembic, httpx, pytest, Docker. MySQL or PostgreSQL for persistence, SQLite acceptable for local practice.
A13: Course arc | B13: Understand the web before writing a server (Units 1-2); get an API running and validate its data (Units 3-6); structure a real application backed by a database (Units 7-9); secure it and make it do real work (Units 10-12); test it and ship it (Units 13-14).
A14: Learning outcome 1 | B14: Explain how HTTP requests and responses work and design REST endpoints that follow accepted conventions.
A15: Learning outcome 2 | B15: Build FastAPI endpoints that validate every input with Pydantic and return correct status codes and error payloads.
... A23: Status | B23: Draft for finalization. Once approved, unit folders and READMEs are scaffolded like the Python, DBMS, and AI courses, then readings are authored unit by unit.

Sheet Recommended Structure
A1: Recommended Curriculum Structure
A2: Why 14 units, how the sequence differs from typical FastAPI courses, and how 45h vs 60h differ.
A4: Topic | B4: Recommendation / Explanation
A5: Recommended unit model | B5: 14 units, one per coherent backend concern. This keeps the course in the same band as Python Semester 1 (11 units, 99 topics) and DBMS (13 units, 106 topics), with a slightly higher topic count because backend work spans more distinct concerns than a single language or query surface.
A6: Why not fewer (8-10 units) | B6: Validation, responses, application structure, and persistence would collapse into oversized units. Each would mix unrelated concepts, and a focused 30-question bank per unit becomes hard to write.
A7: Why not 20+ units | B7: Over-fragments natural topics (routing gets split from parameters, auth from tokens) and leaves no slack for the capstone, review, and assessment.
A8: Why Units 1 and 2 exist | B8: This is the main structural difference from typical FastAPI content, which starts at the first route decorator. Students who never learned HTTP semantics or the event loop can write endpoints but cannot debug them, and they routinely put blocking calls inside async def without understanding why throughput collapses. Two weeks here prevents a semester of magic-thinking.
A9: Why testing precedes deployment | B9: Unit 13 comes before Unit 14 so students ship something they have proven works. Courses that treat tests as an optional appendix produce graduates who deploy untested code.
A10: Relationship to the DBMS course | B10: Unit 8 assumes SQL is already known and does not re-teach it. Only ORM mapping, the session-per-request pattern, relationships, and migrations are new material.
A11: Relationship to Python Semester 2 | B11: Unit 2 revisits decorators, typing, and async specifically as FastAPI uses them, rather than as general language features. Overlap is intentional and framed around the framework.
A12: Pydantic version policy | B12: All material is written for Pydantic v2 syntax. Version 1 differences appear as short compatibility notes, never as parallel material.
A13: Authentication approach | B13: Taught with FastAPI's built-in OAuth2 utilities plus standard libraries (passlib, python-jose) rather than a third-party auth framework, so the concepts transfer to any stack.
A14: Fit to 15-week calendar | B14: One unit per week for Units 1-14, with mini projects assigned alongside the unit that unlocks them. Week 15 is reserved for capstone completion, demos, and the final assessment. Capstone kickoff is deliberately at Week 9, so students build it across the second half.
A15: 45h vs 60h | B15: The 45-hour base runs 3 hours per week (theory + lab as listed in the Week-wise Plan). The 60-hour version adds one lab/project hour each week, spent on the mini project or capstone milestone in progress.
... A17: Open decision: frontend scope | B17: The course is backend-only; Jinja2 templates get a single topic in Unit 12. If students must connect a React or plain-JS frontend, that needs more than the CORS topic currently provides.

Sheet Curriculum (Unit-Topic)
A1: FastAPI Curriculum - Unit and Topic
A2: Clean Unit -> Topic structure (no chapters), in teaching order. Ref is the citation key used by readings, questions, and projects.
A4: Unit | B4: Topic | C4: Ref | D4: Unit No
A5: Unit 1: Web and API Foundations Understand what an API actually is and how a request travels, before writing a single line of server code. | B5: Client and Server: What Happens When You Open a Website | C5: U1.1 | D5: 1
B6: What is an API, and Why Backends Exist | C6: U1.2 | D6: 1
B7: The HTTP Request: Method, URL, Headers, and Body | C7: U1.3 | D7: 1
B8: The HTTP Response: Status Codes, Headers, and Payload | C8: U1.4 | D8: 1
B9: HTTP Methods and Their Meaning: GET, POST, PUT, PATCH, DELETE | C9: U1.5 | D9: 1
B10: JSON: The Language APIs Speak | C10: U1.6 | D10: 1
B11: REST Principles: Resources, Representations, and Statelessness | C11: U1.7 | D11: 1
B12: Designing Good Endpoints: URL Naming, Nouns over Verbs, Consistency | C12: U1.8 | D12: 1
B13: Inspecting Real Traffic: Browser DevTools, curl, and API Clients | C13: U1.9 | D13: 1
B14: Where FastAPI Fits: Frameworks, WSGI vs. ASGI, and Why Speed Matters | C14: U1.10 | D14: 1
A15: Unit 2: Modern Python for FastAPI Pick up the specific Python features FastAPI is built on, so nothing in later units looks like magic. | B15: Type Hints: Annotating Variables, Parameters, and Return Values | C15: U2.1 | D15: 2
B16: Typing Collections: list, dict, Optional, Union, and the Modern Syntax | C16: U2.2 | D16: 2
B17: Data Classes and Typed Objects: Structuring Data in Python | C17: U2.3 | D17: 2
B18: Decorators Revisited: How @app.get(...) Actually Works | C18: U2.4 | D18: 2
B19: Synchronous vs. Asynchronous Execution: Blocking and Waiting | C19: U2.5 | D19: 2
B20: async and await: Coroutines in Plain Language | C20: U2.6 | D20: 2
B21: The Event Loop: One Worker Handling Many Requests | C21: U2.7 | D21: 2
B22: Project Setup: Virtual Environments, pip, and requirements.txt | C22: U2.8 | D22: 2
B23: Reading Library Documentation and Tracebacks Like an Engineer | C23: U2.9 | D23: 2
A24: Unit 3: Your First FastAPI Application Get a real, documented API running on your machine within the first session. | B24: Installing FastAPI and Uvicorn | C24: U3.1 | D24: 3
B25: The Minimal App: FastAPI() and Your First Route | C25: U3.2 | D25: 3
B26: Running the Server with Uvicorn and Live Reload | C26: U3.3 | D26: 3
B27: Path Operation Decorators: Mapping Methods to Functions | C27: U3.4 | D27: 3
B28: Returning Data: Dicts, Lists, and Automatic JSON Conversion | C28: U3.5 | D28: 3
B29: Automatic Interactive Documentation: Swagger UI and ReDoc | C29: U3.6 | D29: 3
B30: OpenAPI: The Schema Behind the Docs | C30: U3.7 | D30: 3
B31: Anatomy of a FastAPI Project: Files, Imports, and the App Object | C31: U3.8 | D31: 3
A32: Unit 4: Request Inputs: Path, Query, Headers, and Cookies Take input from the caller in every form an HTTP request can carry. | B32: Path Parameters: Capturing Values from the URL | C32: U4.1 | D32: 4
B33: Type Conversion and Automatic Validation of Path Parameters | C33: U4.2 | D33: 4
B34: Route Order and Path Conflicts: Why /users/me Must Come First | C34: U4.3 | D34: 4
B35: Query Parameters: Optional Inputs and Default Values | C35: U4.4 | D35: 4
B36: Required vs. Optional Query Parameters | C36: U4.5 | D36: 4
B37: Validating Inputs with Path() and Query(): Length, Range, and Patterns | C37: U4.6 | D37: 4
B38: Enums for Fixed Choices in Paths and Queries | C38: U4.7 | D38: 4
B39: Reading Headers and Cookies | C39: U4.8 | D39: 4
B40: Form Data and When to Use It Instead of JSON | C40: U4.9 | D40: 4
A41: Unit 5: Data Validation with Pydantic Make invalid data impossible to get past the front door of your API. | B41: Why Validation Belongs in the Framework, Not in Every Function | C41: U5.1 | D41: 5
...

Sheet Unit Summary
A1: FastAPI - Unit Summary
A2: Topic counts are live COUNTIF formulas over the Curriculum (Unit-Topic) sheet, so they stay correct if topics are added or removed.
A4: Unit No | B4: Unit | C4: Unit Goal | D4: Topics | E4: Week
A5: 1 | B5: Web and API Foundations | C5: Understand what an API actually is and how a request travels, before writing a single line of server code. | D5: =COUNTIF('Curriculum (Unit-Topic)'!$D$5:$D$133,A5) | E5: 1
A6: 2 | B6: Modern Python for FastAPI | C6: Pick up the specific Python features FastAPI is built on, so nothing in later units looks like magic. | D6: =COUNTIF('Curriculum (Unit-Topic)'!$D$5:$D$133,A6) | E6: 2
A7: 3 | B7: Your First FastAPI Application | C7: Get a real, documented API running on your machine within the first session. | D7: =COUNTIF('Curriculum (Unit-Topic)'!$D$5:$D$133,A7) | E7: 3
A8: 4 | B8: Request Inputs: Path, Query, Headers, and Cookies | C8: Take input from the caller in every form an HTTP request can carry. | D8: =COUNTIF('Curriculum (Unit-Topic)'!$D$5:$D$133,A8) | E8: 4
A9: 5 | B9: Data Validation with Pydantic | C9: Make invalid data impossible to get past the front door of your API. | D9: =COUNTIF('Curriculum (Unit-Topic)'!$D$5:$D$133,A9) | E9: 5
A10: 6 | B10: Responses, Status Codes, and Error Handling | C10: Give callers exactly the data, status, and error messages they can rely on. | D10: =COUNTIF('Curriculum (Unit-Topic)'!$D$5:$D$133,A10) | E10: 6
A11: 7 | B11: Structuring Real Applications: Routers, Dependencies, and Configuration | C11: Grow a single file into a maintainable project without losing your way. | D11: =COUNTIF('Curriculum (Unit-Topic)'!$D$5:$D$133,A11) | E11: 7
A12: 8 | B12: Databases with SQLAlchemy | C12: Connect your API to a real database and keep the data layer clean. | D12: =COUNTIF('Curriculum (Unit-Topic)'!$D$5:$D$133,A12) | E12: 8
A13: 9 | B13: Building a Complete CRUD API | C13: Assemble everything so far into one coherent, production-shaped service. | D13: =COUNTIF('Curriculum (Unit-Topic)'!$D$5:$D$133,A13) | E13: 9
A14: 10 | B14: Authentication and Authorization | C14: Decide who is calling and what they are allowed to do. | D14: =COUNTIF('Curriculum (Unit-Topic)'!$D$5:$D$133,A14) | E14: 10
A15: 11 | B15: Async, Background Tasks, and Calling Other Services | C15: Do slow work without making users wait, and talk to the rest of the world. | D15: =COUNTIF('Curriculum (Unit-Topic)'!$D$5:$D$133,A15) | E15: 11
A16: 12 | B16: Middleware, CORS, File Handling, and Real-Time APIs | C16: Cover the cross-cutting features every real service eventually needs. | D16: =COUNTIF('Curriculum (Unit-Topic)'!$D$5:$D$133,A16) | E16: 12
... A18: 14 | B18: Deployment, Performance, and Production Operations | C18: Take the service off your laptop and keep it healthy under real traffic. | D18: =COUNTIF('Curriculum (Unit-Topic)'!$D$5:$D$133,A18) | E18: 14
B19: Teaching topic total | C19: Project briefs are counted separately: 9 mini projects and 1 capstone project. | D19: =SUM(D5:D18) | E19: -

Sheet Week-wise Plan
A1: FastAPI - 15-Week Plan (45h base, +60h add-on)
A2: Theory/Lab hours are the 45-hour base; the 60-hour version adds +1 lab/project hour each week.
A4: Week | B4: Unit | C4: Topics Covered | D4: Exercise | E4: Coding Challenge | F4: Quiz | G4: Project / Milestone | H4: Theory (h) | I4: Lab (h) | J4: Total 45h | K4: Total 60h
A5: 1 | B5: Unit 1 | C5: HTTP request/response anatomy, methods, status codes, JSON, REST design, DevTools and curl | D5: Trace and document 5 real API calls from a public site using DevTools | E5: Set 1 (10 Q): status-code selection, endpoint naming, JSON shaping | F5: Quiz U1 (10 MCQ) | G5: - | H5: 2 | I5: 1 | J5: 3 | K5: 4
A6: 2 | B6: Unit 2 | C6: Type hints, typing collections, decorators, sync vs async, event loop, venv setup | D6: Annotate an existing untyped script; write a sync vs async timing demo | E6: Set 2 (10 Q): typing, decorators, coroutine behaviour | F6: Quiz U2 (10 MCQ) | G6: - | H6: 1.5 | I6: 1.5 | J6: 3 | K6: 4
A7: 3 | B7: Unit 3 | C7: Install, first route, uvicorn reload, path operations, Swagger UI, OpenAPI schema | D7: Build and document a 5-endpoint 'hello service'; read its OpenAPI JSON | E7: Set 3 (10 Q): route definition, return types, docs behaviour | F7: Quiz U3 (10 MCQ) | G7: Mini Project 1: Unit Converter API (spec issued) | H7: 1 | I7: 2 | J7: 3 | K7: 4
A8: 4 | B8: Unit 4 | C8: Path and query params, route order, Path()/Query() constraints, enums, headers, cookies, forms | D8: Add filtering and validation rules to the converter API | E8: Set 4 (10 Q): parameter validation, route conflicts, enums | F8: Quiz U4 (10 MCQ) | G8: Mini Project 1 due | H8: 1 | I8: 2 | J8: 3 | K8: 4
A9: 5 | B9: Unit 5 | C9: Pydantic models, request bodies, Field constraints, nested models, custom validators | D9: Model a student-admission payload with nested and validated fields | E9: Set 5 (10 Q): schema design, constraint selection, validator logic | F9: Quiz U5 (10 MCQ) | G9: Mini Project 2: Student Records API | H9: 1.5 | I9: 1.5 | J9: 3 | K9: 4
A10: 6 | B10: Unit 6 | C10: Response models, status codes, HTTPException, custom handlers, error payload design | D10: Design a consistent error contract and apply it across an API | E10: Set 6 (10 Q): status-code choice, exception handling, response models | F10: Quiz U6 (10 MCQ) | G10: Mini Project 3: Notes API with CRUD | H10: 1.5 | I10: 1.5 | J10: 3 | K10: 4
A11: 7 | B11: Unit 7 | C11: APIRouter, project layout, dependency injection, Depends, yield dependencies, settings | D11: Refactor a single-file API into a layered, router-based project | E11: Set 7 (10 Q): DI patterns, router wiring, configuration | F11: Quiz U7 (10 MCQ) | G11: - | H11: 1.5 | I11: 1.5 | J11: 3 | K11: 4
A12: 8 | B12: Unit 8 | C12: SQLAlchemy engine and session, ORM models, session-per-request, relationships, Alembic | D12: Model and migrate a catalog schema; wire it to endpoints | E12: Set 8 (10 Q): ORM mapping, session handling, relationship queries | F12: Quiz U8 (10 MCQ) | G12: Mini Project 4: Library Catalog API | H12: 1 | I12: 2 | J12: 3 | K12: 4
A13: 9 | B13: Unit 9 | C13: Resource planning, full CRUD, filtering/sorting/pagination, PUT vs PATCH, service layer | D13: Build a complete resource API end to end and self-review it | E13: Set 9 (10 Q): CRUD semantics, idempotency, pagination | F13: Quiz U9 (10 MCQ) | G13: Capstone kickoff: scope and schema proposal | H13: 1 | I13: 2 | J13: 3 | K13: 4
A14: 10 | B14: Unit 10 | C14: Hashing, login, JWT, OAuth2 password flow, get_current_user, roles, refresh tokens | D14: Add registration, login, and role-gated routes to the CRUD API | E14: Set 10 (10 Q): auth flows, token handling, permission checks | F14: Quiz U10 (10 MCQ) | G14: Mini Project 5: Secure Task Manager | H14: 1.5 | I14: 1.5 | J14: 3 | K14: 4
A15: 11 | B15: Unit 11 | C15: def vs async def, blocking calls, httpx, timeouts and retries, BackgroundTasks, lifespan | D15: Call a public API with retry and timeout handling; queue a follow-up task | E15: Set 11 (10 Q): concurrency reasoning, external-call resilience | F15: Quiz U11 (10 MCQ) | G15: Mini Project 6: Weather Aggregator | H15: 1 | I15: 2 | J15: 3 | K15: 4
A16: 12 | B16: Unit 12 | C16: Middleware, CORS, file upload and download, static files, Jinja2, WebSockets, SSE | D16: Add request-ID logging middleware and a working upload/download flow | E16: Set 12 (10 Q): middleware order, CORS config, file and socket handling | F16: Quiz U12 (10 MCQ) | G16: Mini Projects 7 and 8: File Service, Live Chat | H16: 1 | I16: 2 | J16: 3 | K16: 4
... A19: 15 | B19: Review | C19: Capstone build-out, code review, API design critique, final assessment | D19: Peer review of two capstone APIs against the design checklist | E19: Mixed revision set (20 Q) | F19: Final exam (40 MCQ + 2 coding) | G19: Capstone submission, demo, and viva | H19: 1 | I19: 2 | J19: 3 | K19: 4
B20: Total | H20: =SUM(H5:H19) | I20: =SUM(I5:I19) | J20: =SUM(J5:J19) | K20: =SUM(K5:K19)

Sheet Assessment & QB Plan
A1: FastAPI - Assessment and Question Bank Plan
A2: Per-unit targets. Coding ratio 1:2 = 10 course questions + 20 question-bank questions. Mirrors the Python course plan.
A4: Unit No | B4: Unit | C4: MCQ (total) | D4: MCQ Beg | E4: MCQ Int | F4: MCQ Chal | G4: Coding (course) | H4: Coding (QB) | I4: Bloom focus
A5: 1 | B5: Web and API Foundations | C5: =SUM(D5:F5) | D5: 4 | E5: 3 | F5: 3 | G5: 10 | H5: 20 | I5: Remember / Understand
A6: 2 | B6: Modern Python for FastAPI | C6: =SUM(D6:F6) | D6: 4 | E6: 3 | F6: 3 | G6: 10 | H6: 20 | I6: Understand / Apply
A7: 3 | B7: Your First FastAPI Application | C7: =SUM(D7:F7) | D7: 4 | E7: 3 | F7: 3 | G7: 10 | H7: 20 | I7: Apply
A8: 4 | B8: Request Inputs: Path, Query, Headers, and Cookies | C8: =SUM(D8:F8) | D8: 4 | E8: 3 | F8: 3 | G8: 10 | H8: 20 | I8: Apply
A9: 5 | B9: Data Validation with Pydantic | C9: =SUM(D9:F9) | D9: 4 | E9: 3 | F9: 3 | G9: 10 | H9: 20 | I9: Apply / Analyze
A10: 6 | B10: Responses, Status Codes, and Error Handling | C10: =SUM(D10:F10) | D10: 4 | E10: 3 | F10: 3 | G10: 10 | H10: 20 | I10: Apply / Analyze
A11: 7 | B11: Structuring Real Applications: Routers, Dependencies, and Configuration | C11: =SUM(D11:F11) | D11: 4 | E11: 3 | F11: 3 | G11: 10 | H11: 20 | I11: Analyze / Create
A12: 8 | B12: Databases with SQLAlchemy | C12: =SUM(D12:F12) | D12: 4 | E12: 3 | F12: 3 | G12: 10 | H12: 20 | I12: Apply / Analyze
A13: 9 | B13: Building a Complete CRUD API | C13: =SUM(D13:F13) | D13: 4 | E13: 3 | F13: 3 | G13: 10 | H13: 20 | I13: Apply / Create
A14: 10 | B14: Authentication and Authorization | C14: =SUM(D14:F14) | D14: 4 | E14: 3 | F14: 3 | G14: 10 | H14: 20 | I14: Analyze / Create
A15: 11 | B15: Async, Background Tasks, and Calling Other Services | C15: =SUM(D15:F15) | D15: 4 | E15: 3 | F15: 3 | G15: 10 | H15: 20 | I15: Analyze / Create
A16: 12 | B16: Middleware, CORS, File Handling, and Real-Time APIs | C16: =SUM(D16:F16) | D16: 4 | E16: 3 | F16: 3 | G16: 10 | H16: 20 | I16: Apply / Create
... A18: 14 | B18: Deployment, Performance, and Production Operations | C18: =SUM(D18:F18) | D18: 4 | E18: 3 | F18: 3 | G18: 10 | H18: 20 | I18: Evaluate / Create
B19: Total across 14 units | C19: =SUM(C5:C18) | D19: =SUM(D5:D18) | E19: =SUM(E5:E18) | F19: =SUM(F5:F18) | G19: =SUM(G5:G18) | H19: =SUM(H5:H18) | I19: -
A21: Note | B21: Counts follow the Python Semester 1 plan: 10 MCQ per unit split 4 beginner / 3 intermediate / 3 challenging, plus 10 course coding questions and 20 question-bank coding questions per unit. Because FastAPI questions are API-shaped, coding items should be graded on request/response behaviour (status code, payload shape, validation outcome) rather than on printed output alone.

Sheet Question Taxonomy
A1: FastAPI - Question Taxonomy
A2: Slugs for tagging every question, mirroring the Python course taxonomy. subjects / topics / subTopics map to the MCQ template columns.
A4: subject | B4: topic (unit) | C4: subTopic | D4: Unit
A5: fastapi | B5: web-and-api-foundations | C5: client-and-server-what-happens-when-you-open-a-website | D5: Unit 1: Web and API Foundations
A6: fastapi | C6: what-is-an-api-and-why-backends-exist | D6: Unit 1: Web and API Foundations
A7: fastapi | C7: the-http-request-method-url-headers-and-body | D7: Unit 1: Web and API Foundations
A8: fastapi | C8: the-http-response-status-codes-headers-and-payload | D8: Unit 1: Web and API Foundations
A9: fastapi | C9: http-methods-and-their-meaning-get-post-put-patch-delete | D9: Unit 1: Web and API Foundations
A10: fastapi | C10: json-the-language-apis-speak | D10: Unit 1: Web and API Foundations
A11: fastapi | C11: rest-principles-resources-representations-and-statelessness | D11: Unit 1: Web and API Foundations
A12: fastapi | C12: designing-good-endpoints-url-naming-nouns-over-verbs-consistency | D12: Unit 1: Web and API Foundations
A13: fastapi | C13: inspecting-real-traffic-browser-devtools-curl-and-api-clients | D13: Unit 1: Web and API Foundations
A14: fastapi | C14: where-fastapi-fits-frameworks-wsgi-vs-asgi-and-why-speed-matters | D14: Unit 1: Web and API Foundations
A15: fastapi | B15: modern-python-for-fastapi | C15: type-hints-annotating-variables-parameters-and-return-values | D15: Unit 2: Modern Python for FastAPI
A16: fastapi | C16: typing-collections-list-dict-optional-union-and-the-modern-syntax | D16: Unit 2: Modern Python for FastAPI
A17: fastapi | C17: data-classes-and-typed-objects-structuring-data-in-python | D17: Unit 2: Modern Python for FastAPI
A18: fastapi | C18: decorators-revisited-how-app-get-actually-works | D18: Unit 2: Modern Python for FastAPI
A19: fastapi | C19: synchronous-vs-asynchronous-execution-blocking-and-waiting | D19: Unit 2: Modern Python for FastAPI
A20: fastapi | C20: async-and-await-coroutines-in-plain-language | D20: Unit 2: Modern Python for FastAPI
A21: fastapi | C21: the-event-loop-one-worker-handling-many-requests | D21: Unit 2: Modern Python for FastAPI
A22: fastapi | C22: project-setup-virtual-environments-pip-and-requirements-txt | D22: Unit 2: Modern Python for FastAPI
A23: fastapi | C23: reading-library-documentation-and-tracebacks-like-an-engineer | D23: Unit 2: Modern Python for FastAPI
A24: fastapi | B24: your-first-fastapi-application | C24: installing-fastapi-and-uvicorn | D24: Unit 3: Your First FastAPI Application
A25: fastapi | C25: the-minimal-app-fastapi-and-your-first-route | D25: Unit 3: Your First FastAPI Application
A26: fastapi | C26: running-the-server-with-uvicorn-and-live-reload | D26: Unit 3: Your First FastAPI Application
A27: fastapi | C27: path-operation-decorators-mapping-methods-to-functions | D27: Unit 3: Your First FastAPI Application
A28: fastapi | C28: returning-data-dicts-lists-and-automatic-json-conversion | D28: Unit 3: Your First FastAPI Application
A29: fastapi | C29: automatic-interactive-documentation-swagger-ui-and-redoc | D29: Unit 3: Your First FastAPI Application
A30: fastapi | C30: openapi-the-schema-behind-the-docs | D30: Unit 3: Your First FastAPI Application
A31: fastapi | C31: anatomy-of-a-fastapi-project-files-imports-and-the-app-object | D31: Unit 3: Your First FastAPI Application
A32: fastapi | B32: request-inputs-path-query-headers-and-cookies | C32: path-parameters-capturing-values-from-the-url | D32: Unit 4: Request Inputs: Path, Query, Headers, and Cookies
A33: fastapi | C33: type-conversion-and-automatic-validation-of-path-parameters | D33: Unit 4: Request Inputs: Path, Query, Headers, and Cookies
A34: fastapi | C34: route-order-and-path-conflicts-why-users-me-must-come-first | D34: Unit 4: Request Inputs: Path, Query, Headers, and Cookies
A35: fastapi | C35: query-parameters-optional-inputs-and-default-values | D35: Unit 4: Request Inputs: Path, Query, Headers, and Cookies
A36: fastapi | C36: required-vs-optional-query-parameters | D36: Unit 4: Request Inputs: Path, Query, Headers, and Cookies
A37: fastapi | C37: validating-inputs-with-path-and-query-length-range-and-patterns | D37: Unit 4: Request Inputs: Path, Query, Headers, and Cookies
A38: fastapi | C38: enums-for-fixed-choices-in-paths-and-queries | D38: Unit 4: Request Inputs: Path, Query, Headers, and Cookies
A39: fastapi | C39: reading-headers-and-cookies | D39: Unit 4: Request Inputs: Path, Query, Headers, and Cookies
A40: fastapi | C40: form-data-and-when-to-use-it-instead-of-json | D40: Unit 4: Request Inputs: Path, Query, Headers, and Cookies
A41: fastapi | B41: data-validation-with-pydantic | C41: why-validation-belongs-in-the-framework-not-in-every-function | D41: Unit 5: Data Validation with Pydantic
...

Sheet Projects & Capstone
A1: FastAPI - Project Chapters
A2: Mini projects and capstone projects are maintained as two dedicated course-level chapters, separate from the teaching units.
A4: # | B4: Mini Project | C4: After Unit | D4: Concepts applied
A5: 1 | B5: Unit Converter API | C5: Unit 4 | D5: Path and query parameters, type conversion, validation constraints
A6: 2 | B6: Student Records API with Validation | C6: Unit 5 | D6: Pydantic models, nested schemas, custom validators
A7: 3 | B7: Notes API with Full CRUD and Pagination | C7: Unit 6 | D7: Response models, status codes, error handling, pagination
A8: 4 | B8: Library Catalog API Backed by SQLAlchemy | C8: Unit 8 | D8: ORM models, relationships, session dependency, Alembic
A9: 5 | B9: Secure Task Manager with JWT Authentication | C9: Unit 10 | D9: Password hashing, JWT issue and verify, protected routes, roles
A10: 6 | B10: Weather Aggregator Calling an External API | C10: Unit 11 | D10: httpx, timeouts and retries, background tasks, lifespan
A11: 7 | B11: File Upload and Report Download Service | C11: Unit 12 | D11: UploadFile, storage, streaming responses, static files
A12: 8 | B12: Live Chat Room with WebSockets | C12: Unit 12 | D12: WebSocket endpoints, connection manager, broadcast
A13: 9 | B13: Test Suite for an Existing API | C13: Unit 13 | D13: pytest fixtures, TestClient, test database, dependency overrides
A15: # | B15: Capstone Project | C15: After Unit | D15: Scope
A16: 1 | B16: Complete E-Commerce Backend API | C16: Unit 14 | D16: Users and authentication with roles; product catalog with search, filtering, and pagination; cart and order lifecycle; payment integration stub; admin-only endpoints; background email notifications; full pytest suite with a test database; Dockerized deployment with health checks, structured logging, and a versioned public API. Built across Weeks 9-15 in three milestones.
A18: Placement | B18: Mini project briefs are assigned after the unit named in the 'After Unit' column and stored together in the Mini Projects chapter. The capstone is kicked off at Week 9 and submitted in Week 15, so it is built alongside the second half of the course rather than crammed at the end.
